Workbook
Name Slicer_Most_Played_Artist: #N/A
Name Slicer_Repeat_Song_Rate: #N/A

Sheet CLEANED DATA
A1: User_ID | B1: Age | C1: Country | D1: Streaming Platform | E1: Top Genre | F1: Minutes Streamed Per Day | G1: Number of Songs Liked | H1: Most Played Artist | I1: Subscription Type | J1: Listening Time (Morning/Afternoon/Night) | K1: Discover Weekly Engagement (%) | L1: Repeat Song Rate (%)
A2: U1006 | B2: 49 | C2: Australia | D2: Tidal | E2: Country | F2: 547 | G2: 70 | H2: Billie Eilish | I2: Free | J2: Night | K2: 11.92 | L2: 37.75
A3: U1010 | B3: 40 | C3: South Korea | D3: Deezer | E3: Reggae | F3: 266 | G3: 462 | H3: Taylor Swift | I3: Premium | J3: Afternoon | K3: 87.77 | L3: 8.73
A4: U1039 | B4: 53 | C4: USA | D4: Apple Music | E4: Reggae | F4: 478 | G4: 300 | H4: Taylor Swift | I4: Free | J4: Afternoon | K4: 88.44 | L4: 75.12
A5: U1045 | B5: 42 | C5: India | D5: YouTube | E5: Hip-Hop | F5: 404 | G5: 464 | H5: Ed Sheeran | I5: Premium | J5: Afternoon | K5: 27.4 | L5: 45.91
A6: U1059 | B6: 30 | C6: UK | D6: Amazon Music | E6: Classical | F6: 67 | G6: 191 | H6: BTS | I6: Free | J6: Morning | K6: 85 | L6: 53.98
A7: U1061 | B7: 60 | C7: USA | D7: Apple Music | E7: Rock | F7: 262 | G7: 301 | H7: BTS | I7: Free | J7: Morning | K7: 35.53 | L7: 55.35
A8: U1064 | B8: 26 | C8: South Korea | D8: Tidal | E8: Hip-Hop | F8: 316 | G8: 451 | H8: Billie Eilish | I8: Premium | J8: Night | K8: 32.01 | L8: 23.09
A9: U1072 | B9: 34 | C9: UK | D9: YouTube | E9: Country | F9: 530 | G9: 310 | H9: Ed Sheeran | I9: Free | J9: Afternoon | K9: 33.21 | L9: 18.58
A10: U1076 | B10: 18 | C10: USA | D10: Tidal | E10: Classical | F10: 435 | G10: 165 | H10: BTS | I10: Free | J10: Afternoon | K10: 24.8 | L10: 62.1
A11: U1078 | B11: 14 | C11: Australia | D11: YouTube | E11: Pop | F11: 364 | G11: 171 | H11: Ed Sheeran | I11: Premium | J11: Night | K11: 11.74 | L11: 46.14
A12: U1087 | B12: 40 | C12: India | D12: Tidal | E12: Country | F12: 88 | G12: 153 | H12: Taylor Swift | I12: Premium | J12: Night | K12: 53.63 | L12: 60.28
A13: U1090 | B13: 13 | C13: Australia | D13: Amazon Music | E13: Country | F13: 31 | G13: 354 | H13: Bad Bunny | I13: Free | J13: Morning | K13: 25.42 | L13: 72.64
... A763: U5996 | B763: 38 | C763: Australia | D763: Deezer | E763: Hip-Hop | F763: 225 | G763: 218 | H763: BTS | I763: Premium | J763: Night | K763: 17.08 | L763: 58.23

Sheet TECHNICAL QUES 1
A1: correlation | C1: =CORREL('CLEANED DATA'!K2:K763,'CLEANED DATA'!L2:L763) -> -0.064315021 | D1: there is no correlation between weekly engagement rate & repeat song rate.

Sheet TECHNICAL QUES 2
B1: AGE DISTRIBUTION ANALYSIS
A3: Age | B3: Average of Number of Songs Liked
A4: 13-22 | B4: 264.12593
A5: 23-32 | B5: 263.38788
A6: 33-42 | B6: 259.81132
A7: 43-52 | B7: 233.71508
A8: 53-62 | B8: 249.95161
A9: Grand Total | B9: 253.61549

Sheet Q.1
A1: 1 | B1: What percentage of listeners prefers each artist ? | D1: Artist | E1: Count of Most Played Artist
D2: Bad Bunny | E2: 0.2152231
D3: Billie Eilish | E3: 0.18897638
D4: BTS | E4: 0.18372703
D5: Ed Sheeran | E5: 0.20341207
D6: Taylor Swift | E6: 0.20866142
D7: Grand Total | E7: 1

Sheet Q.2
A1: Average of Repeat Song Rate (%) | B1: Top Genre
A2: Artist | B2: Afternoon | C2: Morning | D2: Night | E2: Grand Total
A3: Bad Bunny | B3: 44.631522 | C3: 46.25322 | D3: 40.792373 | E3: 43.83378 | G3: 2 | H3: How does listening time affects repeat songs rate for each artist?
A4: Billie Eilish | B4: 42.041395 | C4: 45.183958 | D4: 45.29566 | E4: 44.286667
A5: BTS | B5: 41.091951 | C5: 44.475532 | D5: 41.556731 | E5: 42.4005
A6: Ed Sheeran | B6: 42.617333 | C6: 41.190377 | D6: 40.265238 | E6: 41.492065
A7: Taylor Swift | B7: 39.516604 | C7: 40.53 | D7: 40.8425 | E7: 40.310126
A8: Grand Total | B8: 41.963045 | C8: 43.618933 | D8: 41.767143 | E8: 42.444449

Sheet Q.3
A1: Discover Weekly Engagement (%) | B1: Repeat Song Rate (%) | D1: 3 | E1: Does discover weekly engagement relate to repeat song rate?
A2: 11.92 | B2: 37.75
A3: 87.77 | B3: 8.73 | H3: CORREL | I3: =CORREL(A2:A763,B2:B763) -> -0.064315021
A4: 88.44 | B4: 75.12
A5: 27.4 | B5: 45.91
A6: 85 | B6: 53.98
A7: 35.53 | B7: 55.35
A8: 32.01 | B8: 23.09
A9: 33.21 | B9: 18.58
A10: 24.8 | B10: 62.1
A11: 11.74 | B11: 46.14
A12: 53.63 | B12: 60.28
A13: 25.42 | B13: 72.64
A14: 19.66 | B14: 20.12
A15: 43.81 | B15: 55.65
... A763: 17.08 | B763: 58.23

Sheet Q.4
A1: No. of songs liked | B1: Average of Repeat Song Rate (%) | E1: 4 | F1: What is the trend in repeat song rate relative to the no.of songs liked?
A2: 1-100 | B2: 45.89986
A3: 101-200 | B3: 42.44
A4: 201-300 | B4: 42.771776
A5: 301-400 | B5: 41.905772
A6: 401-500 | B6: 39.496051
A7: Grand Total | B7: 42.444449

Sheet HANDLE OUTLIERS
A1: BEFORE TREATMENT OF OUTLIERS | O1: Calcutate mean, median , mode for no.of songs played for each artist? | V1: DATA AFTER TREATING OUTLIERS
A3: Billie Eilish | B3: Taylor Swift | C3: Ed Sheeran | D3: BTS | E3: Bad Bunny | G3: Billie Eilish | H3: Taylor Swift | I3: Ed Sheeran | J3: BTS | K3: Bad Bunny | P3: Billie Eilish | Q3: Taylor Swift | R3: Ed Sheeran | S3: BTS | T3: Bad Bunny | V3: Billie Eilish | W3: Taylor Swift | X3: Ed Sheeran | Y3: BTS | Z3: Bad Bunny | AD3: Billie Eilish | AE3: Taylor Swift | AF3: Ed Sheeran | AG3: BTS | AH3: Bad Bunny
A4: 70 | B4: 462 | C4: 464 | D4: 191 | E4: 354 | G4: 70 | H4: 462 | I4: 464 | J4: 191 | K4: 354 | O4: MEAN | P4: =AVERAGE(A4:A147) -> 248.20833 | Q4: =AVERAGE(B4:B162) -> 269.23899 | R4: =AVERAGE(C4:C158) -> 241.84516 | S4: =AVERAGE(D4:D143) -> 258.95 | T4: =AVERAGE(E4:E167) -> 264.85976 | V4: 70 | W4: 462 | X4: 464 | Y4: 191 | Z4: 354 | AC4: MIN | AD4: =MIN(V4:V147) -> 2 | AE4: =MIN(W4:W147) -> 1 | AF4: =MIN(X4:X147) -> 1 | AG4: =MIN(Y4:Y143) -> 6 | AH4: =MIN(Z4:Z147) -> 4
A5: 451 | B5: 300 | C5: 310 | D5: 301 | E5: 424 | G5: 451 | H5: 300 | I5: 310 | J5: 301 | K5: 424 | O5: MEDIAN | P5: =MEDIAN(A4:A147) -> 240.5 | Q5: =MEDIAN(B4:B162) -> 269 | R5: =MEDIAN(C4:C158) -> 220 | S5: =MEDIAN(D4:D143) -> 257 | T5: =MEDIAN(E4:E167) -> 271 | V5: 451 | W5: 300 | X5: 310 | Y5: 301 | Z5: 424 | AC5: MAX | AD5: =MAX(V4:V147) -> 487 | AE5: =MAX(W4:W147) -> 652 | AF5: =MAX(X4:X147) -> 721 | AG5: =MAX(Y4:Y143) -> 760 | AH5: =MAX(Z4:Z147) -> 737
A6: 102 | B6: 153 | C6: 171 | D6: 165 | E6: 417 | G6: 102 | H6: 153 | I6: 171 | J6: 165 | K6: 417 | O6: MODE | P6: =MODE(A4:A147) -> 369 | Q6: =MODE(B4:B162) -> 291 | R6: =MODE(C4:C158) -> 31 | S6: =MODE(D4:D143) -> 333 | T6: =MODE(E4:E167) -> 321 | V6: 102 | W6: 153 | X6: 171 | Y6: 165 | Z6: 417 | AC6: RANGE | AD6: =AD5-AD4 -> 485 | AE6: =AE5-AE4 -> 651 | AF6: =AF5-AF4 -> 720 | AG6: =AG5-AG4 -> 754 | AH6: =AH5-AH4 -> 733
A7: 274 | B7: 419 | C7: 198 | D7: 88 | E7: 348 | G7: 274 | H7: 419 | I7: 198 | J7: 88 | K7: 348 | V7: 274 | W7: 419 | X7: 198 | Y7: 88 | Z7: 348 | AC7: VARIANCE | AD7: =_xlfn.VAR.P(V4:V147) -> 20570.484 | AE7: =_xlfn.VAR.P(W4:W147) -> 19531.805 | AF7: =_xlfn.VAR.P(X4:X147) -> 22471.602 | AG7: =_xlfn.VAR.P(Y4:Y143) -> 25508.894 | AH7: =_xlfn.VAR.P(Z4:Z147) -> 20689.322
A8: 193 | B8: 112 | C8: 84 | D8: 97 | E8: 274 | G8: 193 | H8: 112 | I8: 84 | J8: 97 | K8: 274 | V8: 193 | W8: 112 | X8: 84 | Y8: 97 | Z8: 274 | AC8: STANDARD DEVIATION | AD8: =SQRT(AD7) -> 143.42414 | AE8: =SQRT(AE7) -> 139.75624 | AF8: =SQRT(AF7) -> 149.90531 | AG8: =SQRT(AG7) -> 159.71504 | AH8: =SQRT(AH7) -> 143.83783
A9: 85 | B9: 435 | C9: 130 | D9: 226 | E9: 491 | G9: 85 | H9: 435 | I9: 130 | J9: 226 | K9: 491 | P9: Billie Eilish | Q9: Taylor Swift | R9: Ed Sheeran | S9: BTS | T9: Bad Bunny | V9: 85 | W9: 435 | X9: 130 | Y9: 226 | Z9: 491
A10: 91 | B10: 212 | C10: 485 | D10: 9 | E10: 461 | G10: 91 | H10: 212 | I10: 485 | J10: 9 | K10: 461 | O10: Q1 | P10: =QUARTILE(A4:A147,1) -> 125 | Q10: =QUARTILE(B4:B162,1) -> 174 | R10: =QUARTILE(C4:C158,1) -> 119 | S10: =QUARTILE(D4:D143,1) -> 130.5 | T10: =QUARTILE(E4:E167,1) -> 140.75 | V10: 91 | W10: 212 | X10: 485 | Y10: 9 | Z10: 461
A11: 168 | B11: 246 | C11: 443 | D11: 228 | E11: 378 | G11: 168 | H11: 246 | I11: 443 | J11: 228 | K11: 378 | O11: Q3 | P11: =QUARTILE(A4:A147,3) -> 369 | Q11: =QUARTILE(B4:B162,3) -> 365.5 | R11: =QUARTILE(C4:C158,3) -> 360 | S11: =QUARTILE(D4:D143,3) -> 382.5 | T11: =QUARTILE(E4:E167,3) -> 379.5 | V11: 168 | W11: 246 | X11: 443 | Y11: 228 | Z11: 378
A12: 44 | B12: 377 | C12: 31 | D12: 333 | E12: 226 | G12: 44 | H12: 377 | I12: 31 | J12: 333 | K12: 226 | O12: IQR | P12: =P11-P10 -> 244 | Q12: =Q11-Q10 -> 191.5 | R12: =R11-R10 -> 241 | S12: =S11-S10 -> 252 | T12: =T11-T10 -> 238.75 | V12: 44 | W12: 377 | X12: 31 | Y12: 333 | Z12: 226
A13: 482 | B13: 245 | C13: 421 | D13: 437 | E13: 248 | G13: 482 | H13: 245 | I13: 421 | J13: 437 | K13: 248 | O13: UPPER FENCE | P13: =P11+1.5*P12 -> 735 | Q13: =Q11+1.5*Q12 -> 652.75 | R13: =R11+1.5*R12 -> 721.5 | S13: =S11+1.5*S12 -> 760.5 | T13: =T11+1.5*T12 -> 737.625 | V13: 482 | W13: 245 | X13: 421 | Y13: 437 | Z13: 248
A14: 431 | B14: 307 | C14: 448 | D14: 428 | E14: 87 | G14: 431 | H14: 307 | I14: 448 | J14: 428 | K14: 87 | O14: LOWER FENCE | P14: =P10-1.5*P12 -> -241 | Q14: =Q10-1.5*Q12 -> -113.25 | R14: =R10-1.5*R12 -> -242.5 | S14: =S10-1.5*S12 -> -247.5 | T14: =T10-1.5*T12 -> -217.375 | V14: 431 | W14: 307 | X14: 448 | Y14: 428 | Z14: 87
A15: 433 | B15: 243 | C15: 256 | D15: 170 | E15: 75 | G15: 433 | H15: 243 | I15: 256 | J15: 170 | K15: 75 | V15: 433 | W15: 243 | X15: 256 | Y15: 170 | Z15: 75
A16: 431 | B16: 429 | C16: 143 | D16: 132 | E16: 212 | G16: 431 | H16: 429 | I16: 143 | J16: 132 | K16: 212 | V16: 431 | W16: 429 | X16: 143 | Y16: 132 | Z16: 212
A17: 7 | B17: 240 | C17: 237 | D17: 99 | E17: 69 | G17: 7 | H17: 240 | I17: 237 | J17: 99 | K17: 69 | O17: BOXPLOT BEFORE TREATMENT OF OUTLIERS | V17: 7 | W17: 240 | X17: 237 | Y17: 99 | Z17: 69
A18: 363 | B18: 222 | C18: 236 | D18: 183 | E18: 343 | G18: 363 | H18: 222 | I18: 236 | J18: 183 | K18: 343 | V18: 363 | W18: 222 | X18: 236 | Y18: 183 | Z18: 343
A19: 24 | B19: 217 | C19: 110 | D19: 31 | E19: 14 | G19: 24 | H19: 217 | I19: 110 | J19: 31 | K19: 14 | V19: 24 | W19: 217 | X19: 110 | Y19: 31 | Z19: 14
A20: 202 | B20: 104 | C20: 354 | D20: 80 | E20: 164 | G20: 202 | H20: 104 | I20: 354 | J20: 80 | K20: 164 | V20: 202 | W20: 104 | X20: 354 | Y20: 80 | Z20: 164
A21: 348 | B21: 108 | C21: 160 | D21: 223 | E21: 243 | G21: 348 | H21: 108 | I21: 160 | J21: 223 | K21: 243 | V21: 348 | W21: 108 | X21: 160 | Y21: 223 | Z21: 243
A22: 105 | B22: 98 | C22: 127 | D22: 192 | E22: 348 | G22: 105 | H22: 98 | I22: 127 | J22: 192 | K22: 348 | V22: 105 | W22: 98 | X22: 127 | Y22: 192 | Z22: 348
A23: 133 | B23: 314 | C23: 143 | D23: 187 | E23: 171 | G23: 133 | H23: 314 | I23: 143 | J23: 187 | K23: 171 | V23: 133 | W23: 314 | X23: 143 | Y23: 187 | Z23: 171
A24: 119 | B24: 289 | C24: 154 | D24: 294 | E24: 306 | G24: 119 | H24: 289 | I24: 154 | J24: 294 | K24: 306 | V24: 119 | W24: 289 | X24: 154 | Y24: 294 | Z24: 306
A25: 352 | B25: 296 | C25: 157 | D25: 479 | E25: 321 | G25: 352 | H25: 296 | I25: 157 | J25: 479 | K25: 321 | V25: 352 | W25: 296 | X25: 157 | Y25: 479 | Z25: 321
A26: 151 | B26: 900 | C26: 119 | D26: 13 | E26: 361 | G26: 151 | H26: 900 | I26: 119 | J26: 13 | K26: 361 | V26: 151 | W26: 652 | X26: 119 | Y26: 13 | Z26: 361
A27: 213 | B27: 192 | C27: 183 | D27: 369 | E27: 333 | G27: 213 | H27: 192 | I27: 183 | J27: 369 | K27: 333 | V27: 213 | W27: 192 | X27: 183 | Y27: 369 | Z27: 333
A28: 235 | B28: 96 | C28: 3 | D28: 162 | E28: 268 | G28: 235 | H28: 96 | I28: 3 | J28: 162 | K28: 268 | V28: 235 | W28: 96 | X28: 3 | Y28: 162 | Z28: 268
A29: 262 | B29: 310 | C29: 290 | D29: 6 | E29: 107 | G29: 262 | H29: 310 | I29: 290 | J29: 6 | K29: 107 | V29: 262 | W29: 310 | X29: 290 | Y29: 6 | Z29: 107
... A143: 292 | B143: 459 | C143: 15 | D143: 218 | E143: 123 | G143: 292 | H143: 459 | I143: 15 | J143: 218 | K143: 123 | V143: 292 | W143: 459 | X143: 15 | Y143: 218 | Z143: 123
A144: 294 | B144: 329 | C144: 46 | E144: 321 | G144: 294 | H144: 329 | I144: 46 | K144: 321 | V144: 294 | W144: 329 | X144: 46 | Z144: 321
A145: 38 | B145: 291 | C145: 135 | E145: 9 | G145: 38 | H145: 291 | I145: 135 | K145: 9 | V145: 38 | W145: 291 | X145: 135 | Z145: 9
A146: 17 | B146: 76 | C146: 417 | E146: 450 | G146: 17 | H146: 76 | I146: 417 | K146: 450 | V146: 17 | W146: 76 | X146: 417 | Z146: 450
A147: 335 | B147: 106 | C147: 249 | E147: 397 | G147: 335 | H147: 106 | I147: 249 | K147: 397 | V147: 335 | W147: 106 | X147: 249 | Z147: 397
B148: 251 | C148: 157 | E148: 379
B149: 298 | C149: 408 | E149: 140
B150: 169 | C150: 84 | E150: 439
B151: 259 | C151: 107 | E151: 482
B152: 93 | C152: 101 | E152: 178
B153: 209 | C153: 129 | E153: 485
B154: 310 | C154: 343 | E154: 31
...

Sheet KPI 1
A3: Average of Minutes Streamed Per Day
A4: 309.87664

Sheet KPI 2
A3: Sum of Number of Songs Liked
A4: 193255

Sheet KPI 3
A3: Average of Discover Weekly Engagement (%)
A4: 50.550472

Sheet KPI 4
A3: Average of Repeat Song Rate (%)
A4: 42.444449

Sheet DASHBOARD
G6: =GETPIVOTDATA("Minutes Streamed Per Day",'KPI 1'!$A$3) -> 309.87664 | J6: =GETPIVOTDATA("Number of Songs Liked",'KPI 2'!$A$3) -> 193255 | M6: =GETPIVOTDATA("Discover Weekly Engagement (%)",'KPI 3'!$A$3) -> 50.550472 | Q6: =GETPIVOTDATA("Repeat Song Rate (%)",'KPI 4'!$A$3) -> 42.444449 | U6: =Q.3!I3 -> -0.064315021
